<?xml version="1.0" ?>
<!-- =================================================================================== -->
<!-- |    This document was autogenerated by xacro from src/rto_core-noetic-devel/rto_description/urdf/robots/rto-3.urdf.xacro | -->
<!-- |    EDITING THIS FILE BY HAND IS NOT RECOMMENDED                                 | -->
<!-- =================================================================================== -->
<robot name="rto">
  <material name="dark_grey">
    <color rgba="0.5882352941176471 0.5882352941176471 0.5882352941176471 1.0"/>
  </material>
  <!-- base_link -->
  <link name="base_link">
    <inertial>
      <mass value="20"/>
      <origin xyz="0 0 0"/>
      <inertia ixx="1.0" ixy="0.0" ixz="0.0" iyy="1.0" iyz="0.0" izz="1.0"/>
    </inertial>
    <visual>
      <origin rpy="0 0 1.570795" xyz="0.01 0 0"/>
      <geometry>
        <mesh filename="package://rto_description/meshes/parts/rto_base.dae" scale="0.01 0.01 0.01"/>
      </geometry>
    </visual>
    <collision>
      <origin rpy="0 0 0" xyz="0 0 0.025"/>
      <geometry>
        <cylinder length="0.05" radius="0.18"/>
      </geometry>
    </collision>
  </link>
  
  <gazebo reference="base_link">
    <turnGravityOff>false</turnGravityOff>
  </gazebo>
  
  <link name="wheel0_link">
    <inertial>
      <mass value="0.00001"/>
      <origin xyz="0 0 0"/>
      <inertia ixx="1.0" ixy="0.0" ixz="0.0" iyy="1.0" iyz="0.0" izz="1.0"/>
    </inertial>
    <visual>
      <origin rpy="0 0 0" xyz="0 0 0"/>
      <geometry>
        <mesh filename="package://rto_description/meshes/parts/rto_wheel.dae" scale="0.01 0.01 0.01"/>
      </geometry>
    </visual>
  </link>
  <gazebo reference="wheel0_link">
    <material>Gazebo/Grey</material>
    <turnGravityOff>false</turnGravityOff>
  </gazebo>
  <joint name="wheel0_joint" type="continuous">
    <origin rpy="0 0 1.0471966666666666" xyz="0.065 0.11 0.04"/>
    <axis xyz="-1 0 0"/>
    <parent link="base_link"/>
    <child link="wheel0_link"/>
  </joint>
  <transmission name="wheel0_joint_trans">
    <type>transmissio_interface/SimpleTransmission</type>
    <joint name="wheel0_joint"/>
    <actuator name="wheel0_motor">
      <hardwareInterface>EffortJointInterface</hardwareInterface>
      <mechanicalReducation>1</mechanicalReducation>
    </actuator>
  </transmission>
  
  <!-- ToDo: Comment out and use to turn the mecanum -->
  <!-- <transmission name="${name}_joint_trans">
            <type>transmission_interface/SimpleTransmission</type>
            <joint name="${name}_joint">
                <hardwareInterface>EffortJointInterface</hardwareInterface>
            </joint>
            <actuator name="${name}_motor">
                <hardwareInterface>EffortJointInterface</hardwareInterface>
                <mechanicalReducation>1</mechanicalReducation>
            </actuator>
        </transmission> -->
  <link name="wheel1_link">
    <inertial>
      <mass value="0.00001"/>
      <origin xyz="0 0 0"/>
      <inertia ixx="1.0" ixy="0.0" ixz="0.0" iyy="1.0" iyz="0.0" izz="1.0"/>
    </inertial>
    <visual>
      <origin rpy="0 0 0" xyz="0 0 0"/>
      <geometry>
        <mesh filename="package://rto_description/meshes/parts/rto_wheel.dae" scale="0.01 0.01 0.01"/>
      </geometry>
    </visual>
  </link>
  <gazebo reference="wheel1_link">
    <material>Gazebo/Grey</material>
    <turnGravityOff>false</turnGravityOff>
  </gazebo>
  <joint name="wheel1_joint" type="continuous">
    <origin rpy="0 0 0" xyz="-0.13 0 0.04"/>
    <axis xyz="1 0 0"/>
    <parent link="base_link"/>
    <child link="wheel1_link"/>
  </joint>
  <transmission name="wheel1_joint_trans">
    <type>transmissio_interface/SimpleTransmission</type>
    <joint name="wheel1_joint"/>
    <actuator name="wheel1_motor">
      <hardwareInterface>EffortJointInterface</hardwareInterface>
      <mechanicalReducation>1</mechanicalReducation>
    </actuator>
  </transmission>
  
  <!-- ToDo: Comment out and use to turn the mecanum -->
  <!-- <transmission name="${name}_joint_trans">
            <type>transmission_interface/SimpleTransmission</type>
            <joint name="${name}_joint">
                <hardwareInterface>EffortJointInterface</hardwareInterface>
            </joint>
            <actuator name="${name}_motor">
                <hardwareInterface>EffortJointInterface</hardwareInterface>
                <mechanicalReducation>1</mechanicalReducation>
            </actuator>
        </transmission> -->
  <link name="wheel2_link">
    <inertial>
      <mass value="0.00001"/>
      <origin xyz="0 0 0"/>
      <inertia ixx="1.0" ixy="0.0" ixz="0.0" iyy="1.0" iyz="0.0" izz="1.0"/>
    </inertial>
    <visual>
      <origin rpy="0 0 0" xyz="0 0 0"/>
      <geometry>
        <mesh filename="package://rto_description/meshes/parts/rto_wheel.dae" scale="0.01 0.01 0.01"/>
      </geometry>
    </visual>
  </link>
  <gazebo reference="wheel2_link">
    <material>Gazebo/Grey</material>
    <turnGravityOff>false</turnGravityOff>
  </gazebo>
  <joint name="wheel2_joint" type="continuous">
    <origin rpy="0 0 -1.0471966666666666" xyz="0.065 -0.11 0.04"/>
    <axis xyz="-1 0 0"/>
    <parent link="base_link"/>
    <child link="wheel2_link"/>
  </joint>
  <transmission name="wheel2_joint_trans">
    <type>transmissio_interface/SimpleTransmission</type>
    <joint name="wheel2_joint"/>
    <actuator name="wheel2_motor">
      <hardwareInterface>EffortJointInterface</hardwareInterface>
      <mechanicalReducation>1</mechanicalReducation>
    </actuator>
  </transmission>
  <!-- ToDo: Comment out and use to turn the mecanum -->
  <!-- <transmission name="${name}_joint_trans">
            <type>transmission_interface/SimpleTransmission</type>
            <joint name="${name}_joint">
                <hardwareInterface>EffortJointInterface</hardwareInterface>
            </joint>
            <actuator name="${name}_motor">
                <hardwareInterface>EffortJointInterface</hardwareInterface>
                <mechanicalReducation>1</mechanicalReducation>
            </actuator>
        </transmission> -->
  <link name="command_bridge_link">
    <inertial>
      <mass value="0.00001"/>
      <origin xyz="0 0 0"/>
      <inertia ixx="1.0" ixy="0.0" ixz="0.0" iyy="1.0" iyz="0.0" izz="1.0"/>
    </inertial>
    <collision>
      <origin rpy="0 0 0" xyz="0 0 0"/>
      <geometry>
        <box size="0.25 0.11 0.16"/>
      </geometry>
    </collision>
  </link>
  <joint name="command_bridge_joint" type="fixed">
    <origin rpy="0 0 1.570795" xyz="-0.05 0 0.13"/>
    <parent link="base_link"/>
    <child link="command_bridge_link"/>
  </joint>
  <!-- <xacro:anglebracketusb name="anglebracketusb" parent="base_link">
            <origin xyz="0.008 0 0.137" rpy="0 0 ${M_PI/2}"/>
        </xacro:anglebracketusb> -->
  <!-- gazebo control -->
  <gazebo>
    <plugin filename="libgazebo_ros_planar_move.so" name="object_controller">
      <commandTopic>cmd_vel</commandTopic>
      <odometryTopic>odom</odometryTopic>
      <odometryFrame>odom</odometryFrame>
      <odometryRate>20</odometryRate>
      <robotBaseFrame>base_link</robotBaseFrame>
      <publishTF>true</publishTF>
    </plugin>
    <plugin filename="libgazebo_ros_control.so" name="gazebo_ros_control"/>
  </gazebo>
  <link name="plate_link">
    <inertial>
      <mass value="0.00001"/>
      <origin xyz="0 0 0"/>
      <inertia ixx="1.0" ixy="0.0" ixz="0.0" iyy="1.0" iyz="0.0" izz="1.0"/>
    </inertial>
    <visual>
      <origin xyz="0 0 0.12"/>
      <geometry>
        <box size="0.002 0.06 0.24"/>
      </geometry>
      <material name="dark_grey"/>
    </visual>
  </link>
  <gazebo reference="plate_link">
    <material>Gazebo/Grey</material>
    <turnGravityOff>false</turnGravityOff>
  </gazebo>
  <joint name="plate_joint" type="fixed">
    <!-- <xacro:insert_block name="origin"/> -->
    <origin xyz="0.05 0 0.07"/>
    <parent link="base_link"/>
    <child link="plate_link"/>
  </joint>
  <link name="bracket_hokuyo_link">
    <inertial>
      <mass value="0.00001"/>
      <origin xyz="0 0 0"/>
      <inertia ixx="1.0" ixy="0.0" ixz="0.0" iyy="1.0" iyz="0.0" izz="1.0"/>
    </inertial>
    <visual>
      <origin rpy="0 0 0" xyz="0 0 0"/>
      <geometry>
        <mesh filename="package://rto_description/meshes/parts/bracket.dae" scale="0.001 0.001 0.001"/>
      </geometry>
      <material name="dark_grey"/>
    </visual>
  </link>
  <gazebo reference="bracket_hokuyo_link">
    <material>Gazebo/DarkGrey</material>
    <turnGravityOff>false</turnGravityOff>
  </gazebo>
  <joint name="bracket_hokuyo_joint" type="fixed">
    <origin rpy="0 0 1.57" xyz="0.101 0 0.15"/>
    <parent link="base_link"/>
    <child link="bracket_hokuyo_link"/>
  </joint>
  <link name="bracket_camera_link">
    <inertial>
      <mass value="0.00001"/>
      <origin xyz="0 0 0"/>
      <inertia ixx="1.0" ixy="0.0" ixz="0.0" iyy="1.0" iyz="0.0" izz="1.0"/>
    </inertial>
    <visual>
      <origin rpy="0 0 0" xyz="0 0 0"/>
      <geometry>
        <mesh filename="package://rto_description/meshes/parts/bracket.dae" scale="0.001 0.000666666667 0.000666666667"/>
      </geometry>
      <material name="dark_grey"/>
    </visual>
  </link>
  <gazebo reference="bracket_camera_link">
    <material>Gazebo/DarkGrey</material>
    <turnGravityOff>false</turnGravityOff>
  </gazebo>
  <joint name="bracket_camera_joint" type="fixed">
    <origin rpy="0 3.14 1.57" xyz="0.084 0 0.271"/>
    <parent link="base_link"/>
    <child link="bracket_camera_link"/>
  </joint>
  <joint name="camera_rgb_joint" type="fixed">
    <origin rpy="0.0 0.0 0.0" xyz="0.1 0.014 0.283"/>
    <parent link="base_link"/>
    <child link="camera_rgb_frame"/>
  </joint>
  <link name="camera_rgb_frame">
    <inertial>
      <mass value="0.001"/>
      <origin xyz="0 0 0"/>
      <inertia ixx="0.0001" ixy="0.0" ixz="0.0" iyy="0.0001" iyz="0.0" izz="0.0001"/>
    </inertial>
  </link>
  <joint name="camera_rgb_optical_joint" type="fixed">
    <origin rpy="-1.570795 0 -1.570795" xyz="0 0 0"/>
    <parent link="camera_rgb_frame"/>
    <child link="camera_rgb_optical_frame"/>
  </joint>
  <link name="camera_rgb_optical_frame">
    <inertial>
      <mass value="0.001"/>
      <origin xyz="0 0 0"/>
      <inertia ixx="0.0001" ixy="0.0" ixz="0.0" iyy="0.0001" iyz="0.0" izz="0.0001"/>
    </inertial>
  </link>
  <joint name="camera_joint" type="fixed">
    <origin rpy="0 0 0" xyz="0 -0.022 0"/>
    <parent link="camera_rgb_frame"/>
    <child link="camera_link"/>
  </joint>
  <link name="camera_link">
    <visual>
      <origin rpy="-1.570795 -3.14159 -1.570795" xyz="-0.01 0 0"/>
      <geometry>
        <mesh filename="package://rto_description/meshes/sensors/asus_xtion_pro_live.dae" scale="0.001 0.001 0.001"/>
      </geometry>
    </visual>
    <collision>
      <origin rpy="0 0 0" xyz="0.0 0.0 0.0"/>
      <geometry>
        <box size="0.0730 .2760 0.0720"/>
      </geometry>
    </collision>
    <inertial>
      <mass value="0.01"/>
      <origin xyz="0 0 0"/>
      <inertia ixx="0.001" ixy="0.0" ixz="0.0" iyy="0.001" iyz="0.0" izz="0.001"/>
    </inertial>
  </link>
  <joint name="camera_depth_joint" type="fixed">
    <origin rpy="0 0 0" xyz="0 0.027 0"/>
    <parent link="camera_rgb_frame"/>
    <child link="camera_depth_frame"/>
  </joint>
  <link name="camera_depth_frame">
    <inertial>
      <mass value="0.01"/>
      <origin xyz="0 0 0"/>
      <inertia ixx="0.001" ixy="0.0" ixz="0.0" iyy="0.001" iyz="0.0" izz="0.001"/>
    </inertial>
  </link>
  <joint name="camera_depth_optical_joint" type="fixed">
    <origin rpy="-1.570795 0 -1.570795" xyz="0 0 0"/>
    <parent link="camera_depth_frame"/>
    <child link="camera_depth_optical_frame"/>
  </joint>
  <link name="camera_depth_optical_frame">
    <inertial>
      <mass value="0.001"/>
      <origin xyz="0 0 0"/>
      <inertia ixx="0.0001" ixy="0.0" ixz="0.0" iyy="0.0001" iyz="0.0" izz="0.0001"/>
    </inertial>
  </link>
  <gazebo reference="camera_link">
    <sensor name="camera" type="depth">
      <always_on>true</always_on>
      <update_rate>20.0</update_rate>
      <camera>
        <horizontal_fov>1.0471966666666666</horizontal_fov>
        <image>
          <format>R8G8B8</format>
          <width>640</width>
          <height>480</height>
        </image>
        <clip>
          <near>0.05</near>
          <far>8.0</far>
        </clip>
      </camera>
      <plugin filename="libgazebo_ros_openni_kinect.so" name="kinect_camera_controller">
        <cameraName>camera</cameraName>
        <alwaysOn>true</alwaysOn>
        <updateRate>10</updateRate>
        <imageTopicName>rgb/image_raw</imageTopicName>
        <depthImageTopicName>depth/image_raw</depthImageTopicName>
        <pointCloudTopicName>depth/points</pointCloudTopicName>
        <cameraInfoTopicName>rgb/camera_info</cameraInfoTopicName>
        <depthImageCameraInfoTopicName>depth/camera_info</depthImageCameraInfoTopicName>
        <frameName>camera_depth_optical_frame</frameName>
        <baseline>0.1</baseline>
        <distortion_k1>0.0</distortion_k1>
        <distortion_k2>0.0</distortion_k2>
        <distortion_k3>0.0</distortion_k3>
        <distortion_t1>0.0</distortion_t1>
        <distortion_t2>0.0</distortion_t2>
        <pointCloudCutoff>0.4</pointCloudCutoff>
      </plugin>
    </sensor>
  </gazebo>
  <joint name="hokuyo_joint" type="fixed">
    <origin rpy="0 0 0" xyz="0.08 0 0.2015"/>
    <parent link="base_link"/>
    <child link="laser_link"/>
  </joint>
  <link name="laser_link">
    <inertial>
      <mass value="0.00001"/>
      <origin xyz="0 0 0"/>
      <inertia ixx="1.0" ixy="0.0" ixz="0.0" iyy="1.0" iyz="0.0" izz="1.0"/>
    </inertial>
    <visual>
      <origin rpy="0 0 1.570795" xyz="0 0 -0.05"/>
      <geometry>
        <mesh filename="package://rto_description/meshes/sensors/hokuyo.dae" scale="0.01 0.01 0.01"/>
      </geometry>
    </visual>
    <collision>
      <origin rpy="0 0 0" xyz="0 0 0.035"/>
      <geometry>
        <cylinder length="0.07" radius="0.02"/>
      </geometry>
    </collision>
  </link>
  <gazebo reference="laser_link">
    <sensor name="hokuyo" type="gpu_ray">
      <!--always_on>true</always_on-->
      <update_rate>40</update_rate>
      <pose>0 0 0 0 0 0</pose>
      <visualize>false</visualize>
      <ray>
        <scan>
          <horizontal>
            <samples>683</samples>
            <resolution>0.36</resolution>
            <min_angle>-2,0944</min_angle>
            <max_angle>2,0944</max_angle>
          </horizontal>
        </scan>
        <range>
          <min>0.03</min>
          <max>5.6</max>
          <resolution>0.01</resolution>
        </range>
        <noise>
          <type>gaussian</type>
          <mean>0.0</mean>
          <stddev>0.005</stddev>
        </noise>
      </ray>
      <plugin filename="libgazebo_ros_gpu_laser.so" name="gazebo_ros_hokuyo_controller">
        <topicName>scan</topicName>
        <frameName>hokuyo_link</frameName>
      </plugin>
    </sensor>
  </gazebo>
</robot>

